2023-11-08 22:23:19,649 ERROR: Exception on /check_job [GET] [in D:\Python\Flask\ERP\venv\lib\site-packages\flask\app.py:1454]
Traceback (most recent call last):
  File "D:\Python\Flask\ERP\venv\lib\site-packages\flask\app.py", line 2070, in wsgi_app
    response = self.full_dispatch_request()
  File "D:\Python\Flask\ERP\venv\lib\site-packages\flask\app.py", line 1515, in full_dispatch_request
    rv = self.handle_user_exception(e)
  File "D:\Python\Flask\ERP\venv\lib\site-packages\flask\app.py", line 1513, in full_dispatch_request
    rv = self.dispatch_request()
  File "D:\Python\Flask\ERP\venv\lib\site-packages\flask\app.py", line 1499, in dispatch_request
    return self.ensure_sync(self.view_functions[rule.endpoint])(**req.view_args)
  File "D:\Python\Flask\ERP\venv\lib\site-packages\flask_login\utils.py", line 271, in decorated_view
    return current_app.login_manager.unauthorized()
  File "D:\Python\Flask\ERP\venv\lib\site-packages\flask_login\login_manager.py", line 165, in unauthorized
    flash(self.login_message, category=self.login_message_category)
  File "D:\Python\Flask\ERP\venv\lib\site-packages\flask\helpers.py", line 391, in flash
    session["_flashes"] = flashes
  File "D:\Python\Flask\ERP\venv\lib\site-packages\flask\sessions.py", line 97, in _fail
    raise RuntimeError(
RuntimeError: The session is unavailable because no secret key was set.  Set the secret_key on the application to something unique and secret.
2023-11-08 22:23:19,650 ERROR: Exception on /check_job [GET] [in D:\Python\Flask\ERP\venv\lib\site-packages\flask\app.py:1454]
Traceback (most recent call last):
  File "D:\Python\Flask\ERP\venv\lib\site-packages\flask\app.py", line 2070, in wsgi_app
    response = self.full_dispatch_request()
  File "D:\Python\Flask\ERP\venv\lib\site-packages\flask\app.py", line 1515, in full_dispatch_request
    rv = self.handle_user_exception(e)
  File "D:\Python\Flask\ERP\venv\lib\site-packages\flask\app.py", line 1513, in full_dispatch_request
    rv = self.dispatch_request()
  File "D:\Python\Flask\ERP\venv\lib\site-packages\flask\app.py", line 1499, in dispatch_request
    return self.ensure_sync(self.view_functions[rule.endpoint])(**req.view_args)
  File "D:\Python\Flask\ERP\venv\lib\site-packages\flask_login\utils.py", line 271, in decorated_view
    return current_app.login_manager.unauthorized()
  File "D:\Python\Flask\ERP\venv\lib\site-packages\flask_login\login_manager.py", line 165, in unauthorized
    flash(self.login_message, category=self.login_message_category)
  File "D:\Python\Flask\ERP\venv\lib\site-packages\flask\helpers.py", line 391, in flash
    session["_flashes"] = flashes
  File "D:\Python\Flask\ERP\venv\lib\site-packages\flask\sessions.py", line 97, in _fail
    raise RuntimeError(
RuntimeError: The session is unavailable because no secret key was set.  Set the secret_key on the application to something unique and secret.
2023-11-08 22:23:19,769 ERROR: Exception on / [GET] [in D:\Python\Flask\ERP\venv\lib\site-packages\flask\app.py:1454]
Traceback (most recent call last):
  File "D:\Python\Flask\ERP\venv\lib\site-packages\flask\app.py", line 2070, in wsgi_app
    response = self.full_dispatch_request()
  File "D:\Python\Flask\ERP\venv\lib\site-packages\flask\app.py", line 1515, in full_dispatch_request
    rv = self.handle_user_exception(e)
  File "D:\Python\Flask\ERP\venv\lib\site-packages\flask\app.py", line 1513, in full_dispatch_request
    rv = self.dispatch_request()
  File "D:\Python\Flask\ERP\venv\lib\site-packages\flask\app.py", line 1499, in dispatch_request
    return self.ensure_sync(self.view_functions[rule.endpoint])(**req.view_args)
  File "D:\Python\Flask\ERP\venv\lib\site-packages\flask_login\utils.py", line 271, in decorated_view
    return current_app.login_manager.unauthorized()
  File "D:\Python\Flask\ERP\venv\lib\site-packages\flask_login\login_manager.py", line 165, in unauthorized
    flash(self.login_message, category=self.login_message_category)
  File "D:\Python\Flask\ERP\venv\lib\site-packages\flask\helpers.py", line 391, in flash
    session["_flashes"] = flashes
  File "D:\Python\Flask\ERP\venv\lib\site-packages\flask\sessions.py", line 97, in _fail
    raise RuntimeError(
RuntimeError: The session is unavailable because no secret key was set.  Set the secret_key on the application to something unique and secret.
2023-11-08 22:23:49,643 ERROR: Exception on /check_job [GET] [in D:\Python\Flask\ERP\venv\lib\site-packages\flask\app.py:1454]
Traceback (most recent call last):
  File "D:\Python\Flask\ERP\venv\lib\site-packages\flask\app.py", line 2070, in wsgi_app
    response = self.full_dispatch_request()
  File "D:\Python\Flask\ERP\venv\lib\site-packages\flask\app.py", line 1515, in full_dispatch_request
    rv = self.handle_user_exception(e)
  File "D:\Python\Flask\ERP\venv\lib\site-packages\flask\app.py", line 1513, in full_dispatch_request
    rv = self.dispatch_request()
  File "D:\Python\Flask\ERP\venv\lib\site-packages\flask\app.py", line 1499, in dispatch_request
    return self.ensure_sync(self.view_functions[rule.endpoint])(**req.view_args)
  File "D:\Python\Flask\ERP\venv\lib\site-packages\flask_login\utils.py", line 271, in decorated_view
    return current_app.login_manager.unauthorized()
  File "D:\Python\Flask\ERP\venv\lib\site-packages\flask_login\login_manager.py", line 165, in unauthorized
    flash(self.login_message, category=self.login_message_category)
  File "D:\Python\Flask\ERP\venv\lib\site-packages\flask\helpers.py", line 391, in flash
    session["_flashes"] = flashes
  File "D:\Python\Flask\ERP\venv\lib\site-packages\flask\sessions.py", line 97, in _fail
    raise RuntimeError(
RuntimeError: The session is unavailable because no secret key was set.  Set the secret_key on the application to something unique and secret.
2023-11-08 22:24:01,959 ERROR: Exception on /orders [GET] [in D:\Python\Flask\ERP\venv\lib\site-packages\flask\app.py:1454]
Traceback (most recent call last):
  File "D:\Python\Flask\ERP\venv\lib\site-packages\flask\app.py", line 2070, in wsgi_app
    response = self.full_dispatch_request()
  File "D:\Python\Flask\ERP\venv\lib\site-packages\flask\app.py", line 1515, in full_dispatch_request
    rv = self.handle_user_exception(e)
  File "D:\Python\Flask\ERP\venv\lib\site-packages\flask\app.py", line 1513, in full_dispatch_request
    rv = self.dispatch_request()
  File "D:\Python\Flask\ERP\venv\lib\site-packages\flask\app.py", line 1499, in dispatch_request
    return self.ensure_sync(self.view_functions[rule.endpoint])(**req.view_args)
  File "D:\Python\Flask\ERP\venv\lib\site-packages\flask_login\utils.py", line 271, in decorated_view
    return current_app.login_manager.unauthorized()
  File "D:\Python\Flask\ERP\venv\lib\site-packages\flask_login\login_manager.py", line 165, in unauthorized
    flash(self.login_message, category=self.login_message_category)
  File "D:\Python\Flask\ERP\venv\lib\site-packages\flask\helpers.py", line 391, in flash
    session["_flashes"] = flashes
  File "D:\Python\Flask\ERP\venv\lib\site-packages\flask\sessions.py", line 97, in _fail
    raise RuntimeError(
RuntimeError: The session is unavailable because no secret key was set.  Set the secret_key on the application to something unique and secret.
2023-11-08 22:24:06,922 ERROR: Exception on /index [GET] [in D:\Python\Flask\ERP\venv\lib\site-packages\flask\app.py:1454]
Traceback (most recent call last):
  File "D:\Python\Flask\ERP\venv\lib\site-packages\flask\app.py", line 2070, in wsgi_app
    response = self.full_dispatch_request()
  File "D:\Python\Flask\ERP\venv\lib\site-packages\flask\app.py", line 1515, in full_dispatch_request
    rv = self.handle_user_exception(e)
  File "D:\Python\Flask\ERP\venv\lib\site-packages\flask\app.py", line 1513, in full_dispatch_request
    rv = self.dispatch_request()
  File "D:\Python\Flask\ERP\venv\lib\site-packages\flask\app.py", line 1499, in dispatch_request
    return self.ensure_sync(self.view_functions[rule.endpoint])(**req.view_args)
  File "D:\Python\Flask\ERP\venv\lib\site-packages\flask_login\utils.py", line 271, in decorated_view
    return current_app.login_manager.unauthorized()
  File "D:\Python\Flask\ERP\venv\lib\site-packages\flask_login\login_manager.py", line 165, in unauthorized
    flash(self.login_message, category=self.login_message_category)
  File "D:\Python\Flask\ERP\venv\lib\site-packages\flask\helpers.py", line 391, in flash
    session["_flashes"] = flashes
  File "D:\Python\Flask\ERP\venv\lib\site-packages\flask\sessions.py", line 97, in _fail
    raise RuntimeError(
RuntimeError: The session is unavailable because no secret key was set.  Set the secret_key on the application to something unique and secret.
2023-11-08 22:25:32,083 INFO: ERP [in D:\Python\Flask\ERP\app\__init__.py:66]
2023-11-08 22:26:36,470 INFO: ERP [in D:\Python\Flask\ERP\app\__init__.py:66]
