2023-10-12 16:18:12,229 ERROR: Exception on /check_job [GET] [in C:\Users\Roman\PycharmProjects\Learning\venv\lib\site-packages\flask\app.py:1454]
Traceback (most recent call last):
  File "C:\Users\Roman\PycharmProjects\Learning\venv\lib\site-packages\flask\app.py", line 2070, in wsgi_app
    response = self.full_dispatch_request()
  File "C:\Users\Roman\PycharmProjects\Learning\venv\lib\site-packages\flask\app.py", line 1515, in full_dispatch_request
    rv = self.handle_user_exception(e)
  File "C:\Users\Roman\PycharmProjects\Learning\venv\lib\site-packages\flask\app.py", line 1513, in full_dispatch_request
    rv = self.dispatch_request()
  File "C:\Users\Roman\PycharmProjects\Learning\venv\lib\site-packages\flask\app.py", line 1499, in dispatch_request
    return self.ensure_sync(self.view_functions[rule.endpoint])(**req.view_args)
  File "C:\Users\Roman\PycharmProjects\Learning\venv\lib\site-packages\flask_login\utils.py", line 271, in decorated_view
    return current_app.login_manager.unauthorized()
  File "C:\Users\Roman\PycharmProjects\Learning\venv\lib\site-packages\flask_login\login_manager.py", line 165, in unauthorized
    flash(self.login_message, category=self.login_message_category)
  File "C:\Users\Roman\PycharmProjects\Learning\venv\lib\site-packages\flask\helpers.py", line 391, in flash
    session["_flashes"] = flashes
  File "C:\Users\Roman\PycharmProjects\Learning\venv\lib\site-packages\flask\sessions.py", line 97, in _fail
    raise RuntimeError(
RuntimeError: The session is unavailable because no secret key was set.  Set the secret_key on the application to something unique and secret.
2023-10-29 18:57:00,745 INFO: ERP [in D:\Python\Flask\ERP\app\__init__.py:72]
2023-10-29 18:57:52,471 INFO: ERP [in D:\Python\Flask\ERP\app\__init__.py:72]
2023-11-06 22:27:41,835 INFO: ERP [in D:\Python\Flask\ERP\app\__init__.py:66]
2023-11-06 23:43:24,688 INFO: ERP [in D:\Python\Flask\ERP\app\__init__.py:66]
2023-11-06 23:44:36,152 ERROR: Exception on /del_data [POST] [in D:\Python\Flask\ERP\venv\lib\site-packages\flask\app.py:1454]
Traceback (most recent call last):
  File "D:\Python\Flask\ERP\venv\lib\site-packages\flask\app.py", line 2070, in wsgi_app
    response = self.full_dispatch_request()
  File "D:\Python\Flask\ERP\venv\lib\site-packages\flask\app.py", line 1515, in full_dispatch_request
    rv = self.handle_user_exception(e)
  File "D:\Python\Flask\ERP\venv\lib\site-packages\flask\app.py", line 1513, in full_dispatch_request
    rv = self.dispatch_request()
  File "D:\Python\Flask\ERP\venv\lib\site-packages\flask\app.py", line 1499, in dispatch_request
    return self.ensure_sync(self.view_functions[rule.endpoint])(**req.view_args)
  File "D:\Python\Flask\ERP\venv\lib\site-packages\flask_login\utils.py", line 272, in decorated_view
    return func(*args, **kwargs)
  File "D:\Python\Flask\ERP\app\routes.py", line 1121, in del_data
    return redirect(url_for('add_part', q=order_client, parts=parts, title='Добавление работ - детали'))
  File "D:\Python\Flask\ERP\venv\lib\site-packages\flask\helpers.py", line 338, in url_for
    return appctx.app.handle_url_build_error(error, endpoint, values)
  File "D:\Python\Flask\ERP\venv\lib\site-packages\flask\helpers.py", line 325, in url_for
    rv = url_adapter.build(
  File "D:\Python\Flask\ERP\venv\lib\site-packages\werkzeug\routing.py", line 2305, in build
    raise BuildError(endpoint, values, method, self)
werkzeug.routing.BuildError: Could not build url for endpoint 'add_part' with values ['parts', 'q', 'title']. Did you mean 'add_order' instead?
2023-11-08 22:17:44,842 INFO: ERP [in D:\Python\Flask\ERP\app\__init__.py:66]
2023-11-08 22:17:49,444 ERROR: Exception on /check_job [GET] [in D:\Python\Flask\ERP\venv\lib\site-packages\flask\app.py:1454]
Traceback (most recent call last):
  File "D:\Python\Flask\ERP\venv\lib\site-packages\flask\app.py", line 2070, in wsgi_app
    response = self.full_dispatch_request()
  File "D:\Python\Flask\ERP\venv\lib\site-packages\flask\app.py", line 1515, in full_dispatch_request
    rv = self.handle_user_exception(e)
  File "D:\Python\Flask\ERP\venv\lib\site-packages\flask\app.py", line 1513, in full_dispatch_request
    rv = self.dispatch_request()
  File "D:\Python\Flask\ERP\venv\lib\site-packages\flask\app.py", line 1499, in dispatch_request
    return self.ensure_sync(self.view_functions[rule.endpoint])(**req.view_args)
  File "D:\Python\Flask\ERP\venv\lib\site-packages\flask_login\utils.py", line 271, in decorated_view
    return current_app.login_manager.unauthorized()
  File "D:\Python\Flask\ERP\venv\lib\site-packages\flask_login\login_manager.py", line 165, in unauthorized
    flash(self.login_message, category=self.login_message_category)
  File "D:\Python\Flask\ERP\venv\lib\site-packages\flask\helpers.py", line 391, in flash
    session["_flashes"] = flashes
  File "D:\Python\Flask\ERP\venv\lib\site-packages\flask\sessions.py", line 97, in _fail
    raise RuntimeError(
RuntimeError: The session is unavailable because no secret key was set.  Set the secret_key on the application to something unique and secret.
2023-11-08 22:17:49,462 ERROR: Exception on /check_job [GET] [in D:\Python\Flask\ERP\venv\lib\site-packages\flask\app.py:1454]
Traceback (most recent call last):
  File "D:\Python\Flask\ERP\venv\lib\site-packages\flask\app.py", line 2070, in wsgi_app
    response = self.full_dispatch_request()
  File "D:\Python\Flask\ERP\venv\lib\site-packages\flask\app.py", line 1515, in full_dispatch_request
    rv = self.handle_user_exception(e)
  File "D:\Python\Flask\ERP\venv\lib\site-packages\flask\app.py", line 1513, in full_dispatch_request
    rv = self.dispatch_request()
  File "D:\Python\Flask\ERP\venv\lib\site-packages\flask\app.py", line 1499, in dispatch_request
    return self.ensure_sync(self.view_functions[rule.endpoint])(**req.view_args)
  File "D:\Python\Flask\ERP\venv\lib\site-packages\flask_login\utils.py", line 271, in decorated_view
    return current_app.login_manager.unauthorized()
  File "D:\Python\Flask\ERP\venv\lib\site-packages\flask_login\login_manager.py", line 165, in unauthorized
    flash(self.login_message, category=self.login_message_category)
  File "D:\Python\Flask\ERP\venv\lib\site-packages\flask\helpers.py", line 391, in flash
    session["_flashes"] = flashes
  File "D:\Python\Flask\ERP\venv\lib\site-packages\flask\sessions.py", line 97, in _fail
    raise RuntimeError(
RuntimeError: The session is unavailable because no secret key was set.  Set the secret_key on the application to something unique and secret.
2023-11-08 22:17:49,462 ERROR: Exception on /check_job [GET] [in D:\Python\Flask\ERP\venv\lib\site-packages\flask\app.py:1454]
Traceback (most recent call last):
  File "D:\Python\Flask\ERP\venv\lib\site-packages\flask\app.py", line 2070, in wsgi_app
    response = self.full_dispatch_request()
  File "D:\Python\Flask\ERP\venv\lib\site-packages\flask\app.py", line 1515, in full_dispatch_request
    rv = self.handle_user_exception(e)
  File "D:\Python\Flask\ERP\venv\lib\site-packages\flask\app.py", line 1513, in full_dispatch_request
    rv = self.dispatch_request()
  File "D:\Python\Flask\ERP\venv\lib\site-packages\flask\app.py", line 1499, in dispatch_request
    return self.ensure_sync(self.view_functions[rule.endpoint])(**req.view_args)
  File "D:\Python\Flask\ERP\venv\lib\site-packages\flask_login\utils.py", line 271, in decorated_view
    return current_app.login_manager.unauthorized()
  File "D:\Python\Flask\ERP\venv\lib\site-packages\flask_login\login_manager.py", line 165, in unauthorized
    flash(self.login_message, category=self.login_message_category)
  File "D:\Python\Flask\ERP\venv\lib\site-packages\flask\helpers.py", line 391, in flash
    session["_flashes"] = flashes
  File "D:\Python\Flask\ERP\venv\lib\site-packages\flask\sessions.py", line 97, in _fail
    raise RuntimeError(
RuntimeError: The session is unavailable because no secret key was set.  Set the secret_key on the application to something unique and secret.
2023-11-08 22:18:19,424 ERROR: Exception on /check_job [GET] [in D:\Python\Flask\ERP\venv\lib\site-packages\flask\app.py:1454]
Traceback (most recent call last):
  File "D:\Python\Flask\ERP\venv\lib\site-packages\flask\app.py", line 2070, in wsgi_app
    response = self.full_dispatch_request()
  File "D:\Python\Flask\ERP\venv\lib\site-packages\flask\app.py", line 1515, in full_dispatch_request
    rv = self.handle_user_exception(e)
  File "D:\Python\Flask\ERP\venv\lib\site-packages\flask\app.py", line 1513, in full_dispatch_request
    rv = self.dispatch_request()
  File "D:\Python\Flask\ERP\venv\lib\site-packages\flask\app.py", line 1499, in dispatch_request
    return self.ensure_sync(self.view_functions[rule.endpoint])(**req.view_args)
  File "D:\Python\Flask\ERP\venv\lib\site-packages\flask_login\utils.py", line 271, in decorated_view
    return current_app.login_manager.unauthorized()
  File "D:\Python\Flask\ERP\venv\lib\site-packages\flask_login\login_manager.py", line 165, in unauthorized
    flash(self.login_message, category=self.login_message_category)
  File "D:\Python\Flask\ERP\venv\lib\site-packages\flask\helpers.py", line 391, in flash
    session["_flashes"] = flashes
  File "D:\Python\Flask\ERP\venv\lib\site-packages\flask\sessions.py", line 97, in _fail
    raise RuntimeError(
RuntimeError: The session is unavailable because no secret key was set.  Set the secret_key on the application to something unique and secret.
